schedule | main | 2025-04-20 23:14:04,588 | INFO | SCHEDULE mode started with airports: ['NCL', 'DUB']
schedule | main | 2025-04-20 23:14:04,694 | INFO | --- SCRAPING NCL (EGNT), city=Newcastle ---
schedule | selenium_utility | 2025-04-20 23:14:04,704 | INFO | Using Chrome binary at: /Applications/Google Chrome.app/Contents/MacOS/Google Chrome
schedule | selenium_utility | 2025-04-20 23:14:04,809 | ERROR | Error initializing Chrome driver: <urlopen error [SSL: CERTIFICATE_VERIFY_FAILED] certificate verify failed: unable to get local issuer certificate (_ssl.c:1000)>
Traceback (most recent call last):
  File "/Library/Frameworks/Python.framework/Versions/3.12/lib/python3.12/urllib/request.py", line 1344, in do_open
    h.request(req.get_method(), req.selector, req.data, headers,
  File "/Library/Frameworks/Python.framework/Versions/3.12/lib/python3.12/http/client.py", line 1327, in request
    self._send_request(method, url, body, headers, encode_chunked)
  File "/Library/Frameworks/Python.framework/Versions/3.12/lib/python3.12/http/client.py", line 1373, in _send_request
    self.endheaders(body, encode_chunked=encode_chunked)
  File "/Library/Frameworks/Python.framework/Versions/3.12/lib/python3.12/http/client.py", line 1322, in endheaders
    self._send_output(message_body, encode_chunked=encode_chunked)
  File "/Library/Frameworks/Python.framework/Versions/3.12/lib/python3.12/http/client.py", line 1081, in _send_output
    self.send(msg)
  File "/Library/Frameworks/Python.framework/Versions/3.12/lib/python3.12/http/client.py", line 1025, in send
    self.connect()
  File "/Library/Frameworks/Python.framework/Versions/3.12/lib/python3.12/http/client.py", line 1468, in connect
    self.sock = self._context.wrap_socket(self.sock,
                ^^^^^^^^^^^^^^^^^^^^^^^^^^^^^^^^^^^^
  File "/Library/Frameworks/Python.framework/Versions/3.12/lib/python3.12/ssl.py", line 455, in wrap_socket
    return self.sslsocket_class._create(
           ^^^^^^^^^^^^^^^^^^^^^^^^^^^^^
  File "/Library/Frameworks/Python.framework/Versions/3.12/lib/python3.12/ssl.py", line 1046, in _create
    self.do_handshake()
  File "/Library/Frameworks/Python.framework/Versions/3.12/lib/python3.12/ssl.py", line 1321, in do_handshake
    self._sslobj.do_handshake()
ssl.SSLCertVerificationError: [SSL: CERTIFICATE_VERIFY_FAILED] certificate verify failed: unable to get local issuer certificate (_ssl.c:1000)

During handling of the above exception, another exception occurred:

Traceback (most recent call last):
  File "/Users/amaellediop/sky_denied_web_app/sky_denied_WEB_APP/data/src/selenium_utility.py", line 66, in gen_driver
    driver = uc.Chrome(version_main=134, options=chrome_options)
             ^^^^^^^^^^^^^^^^^^^^^^^^^^^^^^^^^^^^^^^^^^^^^^^^^^^
  File "/Library/Frameworks/Python.framework/Versions/3.12/lib/python3.12/site-packages/seleniumwire/undetected_chromedriver/webdriver.py", line 61, in __init__
    super().__init__(*args, **kwargs)
  File "/Library/Frameworks/Python.framework/Versions/3.12/lib/python3.12/site-packages/undetected_chromedriver/__init__.py", line 258, in __init__
    self.patcher.auto()
  File "/Library/Frameworks/Python.framework/Versions/3.12/lib/python3.12/site-packages/undetected_chromedriver/patcher.py", line 175, in auto
    release = self.fetch_release_number()
              ^^^^^^^^^^^^^^^^^^^^^^^^^^^
  File "/Library/Frameworks/Python.framework/Versions/3.12/lib/python3.12/site-packages/undetected_chromedriver/patcher.py", line 259, in fetch_release_number
    with urlopen(self.url_repo + path) as conn:
         ^^^^^^^^^^^^^^^^^^^^^^^^^^^^^
  File "/Library/Frameworks/Python.framework/Versions/3.12/lib/python3.12/urllib/request.py", line 215, in urlopen
    return opener.open(url, data, timeout)
           ^^^^^^^^^^^^^^^^^^^^^^^^^^^^^^^
  File "/Library/Frameworks/Python.framework/Versions/3.12/lib/python3.12/urllib/request.py", line 515, in open
    response = self._open(req, data)
               ^^^^^^^^^^^^^^^^^^^^^
  File "/Library/Frameworks/Python.framework/Versions/3.12/lib/python3.12/urllib/request.py", line 532, in _open
    result = self._call_chain(self.handle_open, protocol, protocol +
             ^^^^^^^^^^^^^^^^^^^^^^^^^^^^^^^^^^^^^^^^^^^^^^^^^^^^^^^
  File "/Library/Frameworks/Python.framework/Versions/3.12/lib/python3.12/urllib/request.py", line 492, in _call_chain
    result = func(*args)
             ^^^^^^^^^^^
  File "/Library/Frameworks/Python.framework/Versions/3.12/lib/python3.12/urllib/request.py", line 1392, in https_open
    return self.do_open(http.client.HTTPSConnection, req,
           ^^^^^^^^^^^^^^^^^^^^^^^^^^^^^^^^^^^^^^^^^^^^^^
  File "/Library/Frameworks/Python.framework/Versions/3.12/lib/python3.12/urllib/request.py", line 1347, in do_open
    raise URLError(err)
urllib.error.URLError: <urlopen error [SSL: CERTIFICATE_VERIFY_FAILED] certificate verify failed: unable to get local issuer certificate (_ssl.c:1000)>
schedule | get_flight_by_airport_flightera | 2025-04-20 23:14:04,816 | INFO | Starting Flightera scrape from: https://www.flightera.net/en/airport/Newcastle/EGNT/arrival/2025-04-21%2023_59?
schedule | get_flight_by_airport_flightera | 2025-04-20 23:14:04,817 | ERROR | Flightera scrape failed: 'NoneType' object has no attribute 'get'
Traceback (most recent call last):
  File "/Users/amaellediop/sky_denied_web_app/sky_denied_WEB_APP/data/src/get_flight_by_airport_flightera.py", line 217, in crawl_flighttera_airport_flights
    driver.get(url)
    ^^^^^^^^^^
AttributeError: 'NoneType' object has no attribute 'get'
